2025-04-13 16:22:18,529 - ERROR - Internal Server Error: /update-initiatives/32
Traceback (most recent call last):
  File "C:\Users\emine\OneDrive\Documents\tigray_repo\env\Lib\site-packages\django\core\handlers\exception.py", line 55, in inner
    response = get_response(request)
               ^^^^^^^^^^^^^^^^^^^^^
  File "C:\Users\emine\OneDrive\Documents\tigray_repo\env\Lib\site-packages\django\core\handlers\base.py", line 197, in _get_response
    response = wrapped_callback(request, *callback_args, **callback_kwargs)
               ^^^^^^^^^^^^^^^^^^^^^^^^^^^^^^^^^^^^^^^^^^^^^^^^^^^^^^^^^^^^
  File "C:\Users\emine\OneDrive\Documents\tigray_repo\env\Lib\site-packages\django\views\generic\base.py", line 104, in view
    return self.dispatch(request, *args, **kwargs)
           ^^^^^^^^^^^^^^^^^^^^^^^^^^^^^^^^^^^^^^^
  File "C:\Users\emine\OneDrive\Documents\tigray_repo\env\Lib\site-packages\django\contrib\auth\mixins.py", line 73, in dispatch
    return super().dispatch(request, *args, **kwargs)
           ^^^^^^^^^^^^^^^^^^^^^^^^^^^^^^^^^^^^^^^^^^
  File "C:\Users\emine\OneDrive\Documents\tigray_repo\env\Lib\site-packages\django\views\generic\base.py", line 143, in dispatch
    return handler(request, *args, **kwargs)
           ^^^^^^^^^^^^^^^^^^^^^^^^^^^^^^^^^
  File "C:\Users\emine\OneDrive\Documents\tigray_repo\tigray_data_repo\App\views.py", line 516, in post
    initiative.save()
  File "C:\Users\emine\OneDrive\Documents\tigray_repo\env\Lib\site-packages\django\db\models\base.py", line 891, in save
    self.save_base(
  File "C:\Users\emine\OneDrive\Documents\tigray_repo\env\Lib\site-packages\django\db\models\base.py", line 997, in save_base
    updated = self._save_table(
              ^^^^^^^^^^^^^^^^^
  File "C:\Users\emine\OneDrive\Documents\tigray_repo\env\Lib\site-packages\django\db\models\base.py", line 1129, in _save_table
    updated = self._do_update(
              ^^^^^^^^^^^^^^^^
  File "C:\Users\emine\OneDrive\Documents\tigray_repo\env\Lib\site-packages\django\db\models\base.py", line 1194, in _do_update
    return filtered._update(values) > 0
           ^^^^^^^^^^^^^^^^^^^^^^^^
  File "C:\Users\emine\OneDrive\Documents\tigray_repo\env\Lib\site-packages\django\db\models\query.py", line 1278, in _update
    return query.get_compiler(self.db).execute_sql(CURSOR)
           ^^^^^^^^^^^^^^^^^^^^^^^^^^^^^^^^^^^^^^^^^^^^^^^
  File "C:\Users\emine\OneDrive\Documents\tigray_repo\env\Lib\site-packages\django\db\models\sql\compiler.py", line 2003, in execute_sql
    cursor = super().execute_sql(result_type)
             ^^^^^^^^^^^^^^^^^^^^^^^^^^^^^^^^
  File "C:\Users\emine\OneDrive\Documents\tigray_repo\env\Lib\site-packages\django\db\models\sql\compiler.py", line 1561, in execute_sql
    sql, params = self.as_sql()
                  ^^^^^^^^^^^^^
  File "C:\Users\emine\OneDrive\Documents\tigray_repo\env\Lib\site-packages\django\db\models\sql\compiler.py", line 1966, in as_sql
    val = field.get_db_prep_save(val, connection=self.connection)
          ^^^^^^^^^^^^^^^^^^^^^^^^^^^^^^^^^^^^^^^^^^^^^^^^^^^^^^^
  File "C:\Users\emine\OneDrive\Documents\tigray_repo\env\Lib\site-packages\django\db\models\fields\__init__.py", line 1008, in get_db_prep_save
    return self.get_db_prep_value(value, connection=connection, prepared=False)
           ^^^^^^^^^^^^^^^^^^^^^^^^^^^^^^^^^^^^^^^^^^^^^^^^^^^^^^^^^^^^^^^^^^^^
  File "C:\Users\emine\OneDrive\Documents\tigray_repo\env\Lib\site-packages\django\db\models\fields\__init__.py", line 1536, in get_db_prep_value
    value = self.get_prep_value(value)
            ^^^^^^^^^^^^^^^^^^^^^^^^^^
  File "C:\Users\emine\OneDrive\Documents\tigray_repo\env\Lib\site-packages\django\db\models\fields\__init__.py", line 1531, in get_prep_value
    return self.to_python(value)
           ^^^^^^^^^^^^^^^^^^^^^
  File "C:\Users\emine\OneDrive\Documents\tigray_repo\env\Lib\site-packages\django\db\models\fields\__init__.py", line 1497, in to_python
    raise exceptions.ValidationError(
django.core.exceptions.ValidationError: ['“” value has an invalid date format. It must be in YYYY-MM-DD format.']
2025-04-13 16:52:20,448 - INFO - C:\Users\emine\OneDrive\Documents\tigray_repo\tigray_data_repo\App\models.py changed, reloading.
2025-04-13 16:53:55,782 - INFO - C:\Users\emine\OneDrive\Documents\tigray_repo\tigray_data_repo\App\models.py changed, reloading.
2025-04-13 18:47:40,232 - INFO - C:\Users\emine\OneDrive\Documents\tigray_repo\tigray_data_repo\App\models.py changed, reloading.
2025-04-13 18:48:53,847 - INFO - C:\Users\emine\OneDrive\Documents\tigray_repo\tigray_data_repo\App\views.py changed, reloading.
2025-04-13 19:01:16,655 - INFO - C:\Users\emine\OneDrive\Documents\tigray_repo\tigray_data_repo\App\views.py changed, reloading.
2025-04-13 19:11:02,578 - WARNING - Not Found: /family-sponsors/
